Workbook
Name Beállítás_Egység_Idő_WEB_Conect: Beállítások!$B$35
Name Beállítas_Kalkulator_WEB_Conect: Beállítások!$B$28
Name Beállítás_Megrendelo_WEB_Conect: Beállítások!$B$21
Name Folyamt_Festés_Tipus_Név: 'Folyamatok Alap'!$D$2
Name Folyamt_Fóliázás_Tipus_Név: 'Folyamatok Alap'!$D$1
Name Ma: TODAY()
Name MappaNevAlmappa: [1]Beállítások!$B$10
Name MappaNevAlmappa: Beállítások!$B$11
Name MappaNevGyoker: Beállítások!$B$7
Name Project_Start: 'Gantt diagram'!$I$1
Name Project_Start: Humánerő!$L$1
Name Project_Start: Munkaidő!$L$1
Name Project_Start: Tervezettidő!$L$1
Name Projekt_Deadline: 'Folyamatok tervezése'!$F$1
Name Projekt_File_Név: Beállítások!$B$3
Name Projekt_Név: Beállítások!$B$2
Name Projekt_Start_Date: 'Folyamatok tervezése'!$D$1
Name Projekt_Szám: [1]Beállítások!$B$1
Name Projekt_Szám: Beállítások!$B$1
Name Scrolling_Increment: 'Gantt diagram'!$N$1
Name Scrolling_Increment: Humánerő!$Q$1
Name Scrolling_Increment: Munkaidő!$Q$1
Name Scrolling_Increment: Tervezettidő!$Q$1
Name verzioSzam: Beállítások!$B$4

Sheet Beállítások
A1: Projekt Szám: | B1: {=INDEX(_xlfn.TEXTSPLIT(Projekt_File_Név," - "),,1)} -> ProjektSzám
A2: Projekt Név: | B2: {=INDEX(_xlfn.TEXTSPLIT(Projekt_File_Név," - "),,2)} -> ProjektNév
A3: Projekt file név | B3: {=MID(CELL("filename", A1), SEARCH("[", CELL("filename", A1)) + 1, SEARCH("]",CELL("filename", A1))-SEARCH("[", CELL("filename", A1))-1)} -> ProjektSzám - ProjektNév - 02 - Folyamatok.xlsm
A4: Munkafüzet Verzió: | B4: 00.0.01
A6: Alap:
A7: Győkér mappa név: | B7: https://doorstarkft.sharepoint.com/sites/Gyartas-Dokumentumok/Megosztott dokumentumok/
A9: File adatai:
A10: File Jelenlegi helye: | B10: {=CELL("filename", A10)} -> https://doorstarkft.sharepoint.com/sites/Gyartas-Dokumentumok/Megosztott dokumentumok/Sablon Mappa/ProjektSzám - ProjektNév másolata/Dokumentumok/Táblázatok/[ProjektSzám - ProjektNév - 02 - Folyamatok.xlsm]Beállítások
A11: Almappa: | B11: {=MID(CELL("filename", A1), SEARCH(MappaNevGyoker, CELL("filename", A1)) + LEN(MappaNevGyoker), SEARCH("[",CELL("filename", A1))-(SEARCH(MappaNevGyoker, CELL("filename", A1)) + LEN(MappaNevGyoker))-1)} -> Sablon Mappa/ProjektSzám - ProjektNév másolata/Dokumentumok/Táblázatok
A12: Relatív Almappa: | B12: /Dokumentumok/Táblázatok
A13: File Név Utótag: | B13: - Kiíró.xlsm
A14: File Elnevezése: | B14: {=MID(CELL("filename", $A$1), SEARCH("[", CELL("filename", $A$1)) + 1, SEARCH("]",CELL("filename", $A$1))-SEARCH("[", CELL("filename", $A$1))-1)} -> ProjektSzám - ProjektNév - 02 - Folyamatok.xlsm
A16: "GYM_Összes" Forrás file adatai:
A17: Forrásfile Név Előtag: | B17: =_xlfn.TEXTJOIN(" - ",TRUE,Projekt_Szám,Projekt_Név) -> ProjektSzám - ProjektNév
A18: Forrásfile Név Utótag: | B18: - Gyartasmegrendelő.xlsm
A19: Almappa: | B19: =_xlfn.TEXTBEFORE(B11,B12) -> Sablon Mappa/ProjektSzám - ProjektNév másolata
A20: Forrásfile Elnevezése: | B20: =B17 & B18 -> ProjektSzám - ProjektNév - Gyartasmegrendelő.xlsm
A21: Forrásfile Helye: | B21: =MappaNevGyoker & B19 & "/" & B20 -> https://doorstarkft.sharepoint.com/sites/Gyartas-Dokumentumok/Megosztott dokumentumok/Sablon Mappa/ProjektSzám - ProjektNév másolata/ProjektSzám - ProjektNév - Gyartasmegrendelő.xlsm
A23: "Kalkulátor" Forrás file adatai:
A24: Forrásfile Név Előtag: | B24: =_xlfn.TEXTJOIN(" - ",TRUE,Projekt_Szám,Projekt_Név) -> ProjektSzám - ProjektNév
A25: Forrásfile Név Utótag: | B25: - 01 - Kalkulátor.xlsm
A26: Almappa: | B26: =MappaNevAlmappa -> Sablon Mappa/ProjektSzám - ProjektNév másolata/Dokumentumok/Táblázatok
A27: Forrásfile Elnevezése: | B27: =B24 & B25 -> ProjektSzám - ProjektNév - 01 - Kalkulátor.xlsm
A28: Forrásfile Helye: | B28: =MappaNevGyoker & B26 & "/" & B27 -> https://doorstarkft.sharepoint.com/sites/Gyartas-Dokumentumok/Megosztott dokumentumok/Sablon Mappa/ProjektSzám - ProjektNév másolata/Dokumentumok/Táblázatok/ProjektSzám - ProjektNév - 01 - Kalkulátor.xlsm
A30: "Egység idő" Forrás file adatai:
A31: Forrásfile Név Előtag: | B31: Egység_idő
A32: Forrásfile Név Utótag: | B32: .xlsx
A33: Almappa: | B33: 10 - Adatok
A34: Forrásfile Elnevezése: | B34: =_xlfn.TEXTJOIN("",TRUE,B31,B32) -> Egység_idő.xlsx
A35: Forrásfile Helye: | B35: =MappaNevGyoker & B33 & "/" & B34 -> https://doorstarkft.sharepoint.com/sites/Gyartas-Dokumentumok/Megosztott dokumentumok/10 - Adatok/Egység_idő.xlsx

Sheet Projekt adatok
A1: Sorszám | B1: Prioritás | C1: Cím | D1: Telefonszám | E1: Szám | F1: Név | G1: Megjegyzés | H1: Start Date | I1: Dedline
A2: 1 | B2: 1 | D2: 06707082235 Bogdán Csaba | E2: =IF(Projekt_Szám = 0,"",Projekt_Szám) -> ProjektSzám | F2: =IF(Projekt_Név = 0,"",Projekt_Név) -> ProjektNév | H2: 45823 | I2: 45840

Sheet AlapAdatok
A1: DSMR | B1: Sorszám | C1: Ajtó Menyisége | D1: Ajtó megnevezése | E1: Ajtó Falnyilás Szélessége | F1: Ajtó Szélesség | G1: Ajtó Falnyilás Magassága | H1: Ajtó Hosszúság | I1: Ajtó Falnyilás Vastagság | J1: Ajtó Vastagság | K1: Ajtó Tipus | L1: Ajtó Nyitás | M1: Pánt 3 db Ajtólap Szélesség Feltétel | N1: Pánt 3 db Ajtólap Magasság Feltétel
A2: ProjektSzám | B2: 01
A3: ProjektSzám | B3: 02
A4: ProjektSzám | B4: 03
A5: ProjektSzám | B5: 04
A6: ProjektSzám | B6: 05
A7: ProjektSzám | B7: 06
A8: ProjektSzám | B8: 07
A9: ProjektSzám | B9: 08
A10: ProjektSzám | B10: 09
A11: ProjektSzám | B11: 10
A12: ProjektSzám | B12: 11
A13: ProjektSzám | B13: 12
... A41: ProjektSzám | B41: 40

Sheet Szabászat
A1: DSMR | B1: Sorszám | C1: Hosszúság | D1: Szélesség | E1: Darab | F1: Név | G1: Megjegyzés | H1: Tipus | I1: Alkatrész Megnevezése | J1: Anyag | K1: Vastagság | L1: Felület tipus | M1: Szín | N1: Minta | O1: Column1
A2: ProjektSzám | B2: 01 | C2: 0.2 | D2: 0.2 | E2: 1 | H2: Egyedi Bútorfront | I2: Bútorfront | J2: EOL Mély MDF | K2: 1.8
A3: ProjektSzám | B3: 02 | C3: 0.2 | D3: 0.2 | E3: 1 | H3: Egyedi Bútorfront | I3: Bútorfront | J3: EOL Mély MDF | K3: 1.8
A4: ProjektSzám | B4: 03 | C4: 0.2 | D4: 0.2 | E4: 1 | H4: Egyedi Bútorfront | I4: Bútorfront | J4: EOL Mély MDF | K4: 1.8
A5: ProjektSzám | B5: 04 | C5: 0.2 | D5: 0.2 | E5: 1 | H5: Egyedi Bútorfront | I5: Bútorfront | J5: EOL Mély MDF | K5: 1.8
A6: ProjektSzám | B6: 05 | C6: 0.2 | D6: 0.2 | E6: 1 | H6: Egyedi Bútorfront | I6: Bútorfront | J6: EOL Mély MDF | K6: 1.8
A7: ProjektSzám | B7: 06 | C7: 0.2 | D7: 0.2 | E7: 1 | H7: Egyedi Bútorfront | I7: Bútorfront | J7: EOL Mély MDF | K7: 1.8
A8: ProjektSzám | B8: 07 | C8: 0.2 | D8: 0.2 | E8: 1 | H8: Egyedi Bútorfront | I8: Bútorfront | J8: EOL Mély MDF | K8: 1.8
A9: ProjektSzám | B9: 08 | C9: 0.2 | D9: 0.2 | E9: 1 | H9: Egyedi Bútorfront | I9: Bútorfront | J9: EOL Mély MDF | K9: 1.8
A10: ProjektSzám | B10: 09 | C10: 0.2 | D10: 0.2 | E10: 1 | H10: Egyedi Bútorfront | I10: Bútorfront | J10: EOL Mély MDF | K10: 1.8
A11: ProjektSzám | B11: 11 | C11: 0.2 | D11: 0.2 | E11: 1 | H11: Egyedi Bútorfront | I11: Bútorfront | J11: EOL Mély MDF | K11: 1.8
A12: ProjektSzám | B12: 12 | C12: 0.2 | D12: 0.2 | E12: 1 | H12: Egyedi Bútorfront | I12: Bútorfront | J12: EOL Mély MDF | K12: 1.8
A13: ProjektSzám | B13: 13 | C13: 0.2 | D13: 0.2 | E13: 1 | H13: Egyedi Bútorfront | I13: Bútorfront | J13: EOL Mély MDF | K13: 1.8
... A40: ProjektSzám | B40: 40 | C40: 0.2 | D40: 0.2 | E40: 1 | H40: Egyedi Bútorfront | I40: Bútorfront | J40: EOL Mély MDF | K40: 1.8
A41: ProjektSzám | B41: 41 | C41: 0.2 | D41: 0.2 | E41: 11 | H41: Egyedi Bútorfront | I41: Bútorfront | J41: EOL Mély MDF | K41: 1.8 | L41: Festett
A42: ProjektSzám | B42: 42 | C42: 0.2 | D42: 0.2 | E42: 1 | H42: Egyedi Bútorfront | I42: Bútorfront | J42: EOL Mély MDF | K42: 1.8 | L42: Festett
A43: ProjektSzám | B43: 43 | C43: 0.2 | D43: 0.2 | E43: 1 | H43: Egyedi Bútorfront | I43: Bútorfront | J43: EOL Mély MDF | K43: 1.8 | L43: Festett
A44: ProjektSzám | B44: 44 | C44: 0.2 | D44: 0.2 | E44: 1 | H44: Egyedi Bútorfront | I44: Bútorfront | J44: EOL Mély MDF | K44: 1.8
A45: ProjektSzám | B45: 45 | C45: 0.2 | D45: 0.2 | E45: 1 | H45: Egyedi Bútorfront | I45: Bútorfront | J45: EOL Mély MDF | K45: 1.8
A46: ProjektSzám | B46: 46 | C46: 0.2 | D46: 0.2 | E46: 1 | H46: Egyedi Bútorfront | I46: Bútorfront | J46: EOL Mély MDF | K46: 1.8
A47: ProjektSzám | B47: 47 | C47: 0.2 | D47: 0.2 | E47: 1 | H47: Egyedi Bútorfront | I47: Bútorfront | J47: EOL Mély MDF | K47: 1.8
A48: ProjektSzám | B48: 48 | C48: 0.2 | D48: 0.2 | E48: 1 | H48: Egyedi Bútorfront | I48: Bútorfront | J48: EOL Mély MDF | K48: 1.8
A49: ProjektSzám | B49: 49 | C49: 0.2 | D49: 0.2 | E49: 1 | H49: Egyedi Bútorfront | I49: Bútorfront | J49: EOL Mély MDF | K49: 1.8 | L49: Fóliás
A50: ProjektSzám | B50: 50 | C50: 0.2 | D50: 0.2 | E50: 1 | H50: Egyedi Bútorfront | I50: Bútorfront | J50: EOL Mély MDF | K50: 1.8 | L50: Fóliás
A51: ProjektSzám | B51: 51 | C51: 0.2 | D51: 0.2 | E51: 1 | H51: Egyedi Bútorfront | I51: Bútorfront | J51: EOL Mély MDF | K51: 1.8 | L51: Fóliás

Sheet Folyamatok Alap
D1: Fóliás
D2: Festett
B4: Termékek Tipus | E4: Tábla neve | F4: Tipus | G4: jel
B5: Bútorfront | E5: Folyamat_Gyártáselőkészítés | F5: {=INDEX(_xlfn.TEXTSPLIT(FolyamatVált_Táblázatok[[#This Row],[Tábla neve]],"_"),,1)} -> Folyamat | G5: {=INDEX(_xlfn.TEXTSPLIT(FolyamatVált_Táblázatok[[#This Row],[Tábla neve]],"_"),,2)} -> Gyártáselőkészítés
B6: Falpanel | E6: Folyamat_Ajtólap | F6: {=INDEX(_xlfn.TEXTSPLIT(FolyamatVált_Táblázatok[[#This Row],[Tábla neve]],"_"),,1)} -> Folyamat | G6: {=INDEX(_xlfn.TEXTSPLIT(FolyamatVált_Táblázatok[[#This Row],[Tábla neve]],"_"),,2)} -> Ajtólap
B7: Dísztok | E7: Folyamat_Tokmag | F7: {=INDEX(_xlfn.TEXTSPLIT(FolyamatVált_Táblázatok[[#This Row],[Tábla neve]],"_"),,1)} -> Folyamat | G7: {=INDEX(_xlfn.TEXTSPLIT(FolyamatVált_Táblázatok[[#This Row],[Tábla neve]],"_"),,2)} -> Tokmag
B8: FAF T | E8: Folyamat_TokmagTU | F8: {=INDEX(_xlfn.TEXTSPLIT(FolyamatVált_Táblázatok[[#This Row],[Tábla neve]],"_"),,1)} -> Folyamat | G8: {=INDEX(_xlfn.TEXTSPLIT(FolyamatVált_Táblázatok[[#This Row],[Tábla neve]],"_"),,2)} -> TokmagTU
B9: FAF TN | E9: Folyamat_Borítás | F9: {=INDEX(_xlfn.TEXTSPLIT(FolyamatVált_Táblázatok[[#This Row],[Tábla neve]],"_"),,1)} -> Folyamat | G9: {=INDEX(_xlfn.TEXTSPLIT(FolyamatVált_Táblázatok[[#This Row],[Tábla neve]],"_"),,2)} -> Borítás
B10: FAF TN Ket sz. | E10: Folyamat_Bútorfront | F10: {=INDEX(_xlfn.TEXTSPLIT(FolyamatVált_Táblázatok[[#This Row],[Tábla neve]],"_"),,1)} -> Folyamat | G10: {=INDEX(_xlfn.TEXTSPLIT(FolyamatVált_Táblázatok[[#This Row],[Tábla neve]],"_"),,2)} -> Bútorfront
B11: Falcos | E11: Folyamat_Blende | F11: {=INDEX(_xlfn.TEXTSPLIT(FolyamatVált_Táblázatok[[#This Row],[Tábla neve]],"_"),,1)} -> Folyamat | G11: {=INDEX(_xlfn.TEXTSPLIT(FolyamatVált_Táblázatok[[#This Row],[Tábla neve]],"_"),,2)} -> Blende
B12: Falsíkban | E12: Folyamat_Falpanel | F12: {=INDEX(_xlfn.TEXTSPLIT(FolyamatVált_Táblázatok[[#This Row],[Tábla neve]],"_"),,1)} -> Folyamat | G12: {=INDEX(_xlfn.TEXTSPLIT(FolyamatVált_Táblázatok[[#This Row],[Tábla neve]],"_"),,2)} -> Falpanel
B13: FEF T
B14: FEF TN
B15: FEF TN Ket sz.
B16: Kétsz. Sikba
B17: Kétsz. Tokba
B18: Pivot
B19: Síkban
B20: Sikban Tok
B21: Sikban Ajtólap
B22: Sikban Blende
B23: Sikban Borítás
B24: Tokba
... B32: TUT Sikba
A36: DSMR | B36: Feladat Rövidnév | C36: Feladat ID | D36: Feladat leírás | E36: Megnevezés | F36: Főfeladat Megnevezése | G36: Sorszám | H36: Feladat Tipus | I36: Kockázat | J36: Részleg 02 | K36: Részleg 01 | L36: Felelős | M36: Támogató | N36: Volumen | O36: Egység idő | P36: Humánerő | Q36: Ősszefoglaló feladat ID | R36: Szülő feladat Rővidnév | S36: Szülő feladat ID | T36: Feladat Függöség Tipusa | U36: Feladat Késleltetés | V36: Feladat Elinditása Részleges készültség esetén | W36: Extra nap
A37: =Projekt_Szám -> ProjektSzám | B37: GyI-E.00 | C37: =Folyamat_Sor_Gyártáselőkészítés[[#This Row],[DSMR]] & "-" & Folyamat_Sor_Gyártáselőkészítés[[#This Row],[Feladat Rövidnév]] -> ProjektSzám-GyI-E.00 | D37: =_xlfn.XLOOKUP(Folyamat_Sor_Gyártáselőkészítés[[#This Row],[Feladat Rövidnév]],Feladat_Egység_idő1[Feladat Rövidnév],Feladat_Egység_idő1[Feladat leírás],0,0,1) -> Előkészítés | E37: =_xlfn.XLOOKUP(Folyamat_Sor_Gyártáselőkészítés[[#This Row],[Feladat Rövidnév]],Feladat_Egység_idő1[Feladat Rövidnév],Feladat_Egység_idő1[Feladat leírás],0,0,1) -> Előkészítés | F37: =_xlfn.LET( _xlpm.megnevezés,"Előkészítés", IF(_xlpm.megnevezés=Folyamat_Sor_Gyártáselőkészítés[[#This Row],[Megnevezés]],"",_xlpm.megnevezés) ) | G37: 00 | H37: Összetett folyamat | I37: Terv szerint | J37: Gyártás Iroda | N37: 1 | O37: =_xlfn.XLOOKUP(Folyamat_Sor_Gyártáselőkészítés[[#This Row],[Feladat Rövidnév]],Feladat_Egység_idő1[Feladat Rövidnév],Feladat_Egység_idő1[Egység idő],0,0,1) -> 0 | P37: =_xlfn.XLOOKUP(Folyamat_Sor_Gyártáselőkészítés[[#This Row],[Feladat Rövidnév]],Feladat_Egység_idő1[Feladat Rövidnév],Feladat_Egység_idő1[Humánerő],0,0,1) -> 0 | V37: 1 | W37: 5
A38: =Projekt_Szám -> ProjektSzám | B38: GyI-E.01 | C38: =Folyamat_Sor_Gyártáselőkészítés[[#This Row],[DSMR]] & "-" & Folyamat_Sor_Gyártáselőkészítés[[#This Row],[Feladat Rövidnév]] -> ProjektSzám-GyI-E.01 | D38: =_xlfn.XLOOKUP(Folyamat_Sor_Gyártáselőkészítés[[#This Row],[Feladat Rövidnév]],Feladat_Egység_idő1[Feladat Rövidnév],Feladat_Egység_idő1[Feladat leírás],0,0,1) -> Megrendelés átadó megbeszélés | E38: =_xlfn.XLOOKUP(Folyamat_Sor_Gyártáselőkészítés[[#This Row],[Feladat Rövidnév]],Feladat_Egység_idő1[Feladat Rövidnév],Feladat_Egység_idő1[Feladat leírás],0,0,1) -> Megrendelés átadó megbeszélés | F38: =_xlfn.LET( _xlpm.megnevezés,"Előkészítés", IF(_xlpm.megnevezés=Folyamat_Sor_Gyártáselőkészítés[[#This Row],[Megnevezés]],"",_xlpm.megnevezés) ) -> Előkészítés | G38: 01 | H38: Folyamat | I38: Terv szerint | J38: Gyártás Iroda | K38: Műszaki tervezés | L38: Simon Kázmér | N38: 1 | O38: =_xlfn.XLOOKUP(Folyamat_Sor_Gyártáselőkészítés[[#This Row],[Feladat Rövidnév]],Feladat_Egység_idő1[Feladat Rövidnév],Feladat_Egység_idő1[Egység idő],0,0,1) -> 0.041666667 | P38: =_xlfn.XLOOKUP(Folyamat_Sor_Gyártáselőkészítés[[#This Row],[Feladat Rövidnév]],Feladat_Egység_idő1[Feladat Rövidnév],Feladat_Egység_idő1[Humánerő],0,0,1) -> 1 | Q38: =Folyamat_Sor_Gyártáselőkészítés[[#This Row],[DSMR]] & "-GyI-E.00" -> ProjektSzám-GyI-E.00 | R38: GyI-E.00 | S38: =Folyamat_Sor_Gyártáselőkészítés[[#This Row],[DSMR]] & "-" & Folyamat_Sor_Gyártáselőkészítés[[#This Row],[Szülő feladat Rővidnév]] -> ProjektSzám-GyI-E.00 | T38: SS | V38: 1
A39: =Projekt_Szám -> ProjektSzám | B39: GyI-E.02 | C39: =Folyamat_Sor_Gyártáselőkészítés[[#This Row],[DSMR]] & "-" & Folyamat_Sor_Gyártáselőkészítés[[#This Row],[Feladat Rövidnév]] -> ProjektSzám-GyI-E.02 | D39: =_xlfn.XLOOKUP(Folyamat_Sor_Gyártáselőkészítés[[#This Row],[Feladat Rövidnév]],Feladat_Egység_idő1[Feladat Rövidnév],Feladat_Egység_idő1[Feladat leírás],0,0,1) -> Információk beszerzése | E39: =_xlfn.XLOOKUP(Folyamat_Sor_Gyártáselőkészítés[[#This Row],[Feladat Rövidnév]],Feladat_Egység_idő1[Feladat Rövidnév],Feladat_Egység_idő1[Feladat leírás],0,0,1) -> Információk beszerzése | F39: =_xlfn.LET( _xlpm.megnevezés,"Előkészítés", IF(_xlpm.megnevezés=Folyamat_Sor_Gyártáselőkészítés[[#This Row],[Megnevezés]],"",_xlpm.megnevezés) ) -> Előkészítés | G39: 02 | H39: Folyamat | I39: Terv szerint | J39: Gyártás Iroda | K39: Műszaki tervezés | L39: Simon Kázmér | N39: 1 | O39: =_xlfn.XLOOKUP(Folyamat_Sor_Gyártáselőkészítés[[#This Row],[Feladat Rövidnév]],Feladat_Egység_idő1[Feladat Rövidnév],Feladat_Egység_idő1[Egység idő],0,0,1) -> 0.041666667 | P39: =_xlfn.XLOOKUP(Folyamat_Sor_Gyártáselőkészítés[[#This Row],[Feladat Rövidnév]],Feladat_Egység_idő1[Feladat Rövidnév],Feladat_Egység_idő1[Humánerő],0,0,1) -> 1 | Q39: =Folyamat_Sor_Gyártáselőkészítés[[#This Row],[DSMR]] & "-GyI-E.00" -> ProjektSzám-GyI-E.00 | R39: GyI-E.01 | S39: =Folyamat_Sor_Gyártáselőkészítés[[#This Row],[DSMR]] & "-" & Folyamat_Sor_Gyártáselőkészítés[[#This Row],[Szülő feladat Rővidnév]] -> ProjektSzám-GyI-E.01 | T39: SS | V39: 1
A40: =Projekt_Szám -> ProjektSzám | B40: GyI-E.02.01 | C40: =Folyamat_Sor_Gyártáselőkészítés[[#This Row],[DSMR]] & "-" & Folyamat_Sor_Gyártáselőkészítés[[#This Row],[Feladat Rövidnév]] -> ProjektSzám-GyI-E.02.01 | D40: =_xlfn.XLOOKUP(Folyamat_Sor_Gyártáselőkészítés[[#This Row],[Feladat Rövidnév]],Feladat_Egység_idő1[Feladat Rövidnév],Feladat_Egység_idő1[Feladat leírás],0,0,1) -> 0 | E40: =_xlfn.XLOOKUP(Folyamat_Sor_Gyártáselőkészítés[[#This Row],[Feladat Rövidnév]],Feladat_Egység_idő1[Feladat Rövidnév],Feladat_Egység_idő1[Feladat leírás],0,0,1) -> 0 | F40: =_xlfn.LET( _xlpm.megnevezés,"Előkészítés", IF(_xlpm.megnevezés=Folyamat_Sor_Gyártáselőkészítés[[#This Row],[Megnevezés]],"",_xlpm.megnevezés) ) -> Előkészítés | G40: 03 | H40: Folyamat | I40: Terv szerint | J40: Gyártás Iroda | K40: Műszaki tervezés | L40: Simon Kázmér | M40: Szántói Gábor | N40: 1 | O40: =_xlfn.XLOOKUP(Folyamat_Sor_Gyártáselőkészítés[[#This Row],[Feladat Rövidnév]],Feladat_Egység_idő1[Feladat Rövidnév],Feladat_Egység_idő1[Egység idő],0,0,1) -> 0 | P40: =_xlfn.XLOOKUP(Folyamat_Sor_Gyártáselőkészítés[[#This Row],[Feladat Rövidnév]],Feladat_Egység_idő1[Feladat Rövidnév],Feladat_Egység_idő1[Humánerő],0,0,1) -> 0 | Q40: =Folyamat_Sor_Gyártáselőkészítés[[#This Row],[DSMR]] & "-GyI-E.00" -> ProjektSzám-GyI-E.00 | R40: GyI-E.02 | S40: =Folyamat_Sor_Gyártáselőkészítés[[#This Row],[DSMR]] & "-" & Folyamat_Sor_Gyártáselőkészítés[[#This Row],[Szülő feladat Rővidnév]] -> ProjektSzám-GyI-E.02 | T40: FS | V40: 1
A41: =Projekt_Szám -> ProjektSzám | B41: GyI-E.03 | C41: =Folyamat_Sor_Gyártáselőkészítés[[#This Row],[DSMR]] & "-" & Folyamat_Sor_Gyártáselőkészítés[[#This Row],[Feladat Rövidnév]] -> ProjektSzám-GyI-E.03 | D41: =_xlfn.XLOOKUP(Folyamat_Sor_Gyártáselőkészítés[[#This Row],[Feladat Rövidnév]],Feladat_Egység_idő1[Feladat Rövidnév],Feladat_Egység_idő1[Feladat leírás],0,0,1) -> Megerndelőlap elenőrzése | E41: =_xlfn.XLOOKUP(Folyamat_Sor_Gyártáselőkészítés[[#This Row],[Feladat Rövidnév]],Feladat_Egység_idő1[Feladat Rövidnév],Feladat_Egység_idő1[Feladat leírás],0,0,1) -> Megerndelőlap elenőrzése | F41: =_xlfn.LET( _xlpm.megnevezés,"Előkészítés", IF(_xlpm.megnevezés=Folyamat_Sor_Gyártáselőkészítés[[#This Row],[Megnevezés]],"",_xlpm.megnevezés) ) -> Előkészítés | G41: 04 | H41: Folyamat | I41: Terv szerint | J41: Gyártás Iroda | K41: Műszaki tervezés | L41: Simon Kázmér | N41: 1 | O41: =_xlfn.XLOOKUP(Folyamat_Sor_Gyártáselőkészítés[[#This Row],[Feladat Rövidnév]],Feladat_Egység_idő1[Feladat Rövidnév],Feladat_Egység_idő1[Egység idő],0,0,1) -> 0.041666667 | P41: =_xlfn.XLOOKUP(Folyamat_Sor_Gyártáselőkészítés[[#This Row],[Feladat Rövidnév]],Feladat_Egység_idő1[Feladat Rövidnév],Feladat_Egység_idő1[Humánerő],0,0,1) -> 1 | Q41: =Folyamat_Sor_Gyártáselőkészítés[[#This Row],[DSMR]] & "-GyI-E.00" -> ProjektSzám-GyI-E.00 | R41: GyI-E.02.01 | S41: =Folyamat_Sor_Gyártáselőkészítés[[#This Row],[DSMR]] & "-" & Folyamat_Sor_Gyártáselőkészítés[[#This Row],[Szülő feladat Rővidnév]] -> ProjektSzám-GyI-E.02.01 | T41: SS | V41: 1
A42: =Projekt_Szám -> ProjektSzám | B42: GyI-E.04 | C42: =Folyamat_Sor_Gyártáselőkészítés[[#This Row],[DSMR]] & "-" & Folyamat_Sor_Gyártáselőkészítés[[#This Row],[Feladat Rövidnév]] -> ProjektSzám-GyI-E.04 | D42: =_xlfn.XLOOKUP(Folyamat_Sor_Gyártáselőkészítés[[#This Row],[Feladat Rövidnév]],Feladat_Egység_idő1[Feladat Rövidnév],Feladat_Egység_idő1[Feladat leírás],0,0,1) -> Információk elenőrzése | E42: =_xlfn.XLOOKUP(Folyamat_Sor_Gyártáselőkészítés[[#This Row],[Feladat Rövidnév]],Feladat_Egység_idő1[Feladat Rövidnév],Feladat_Egység_idő1[Feladat leírás],0,0,1) -> Információk elenőrzése | F42: =_xlfn.LET( _xlpm.megnevezés,"Előkészítés", IF(_xlpm.megnevezés=Folyamat_Sor_Gyártáselőkészítés[[#This Row],[Megnevezés]],"",_xlpm.megnevezés) ) -> Előkészítés | G42: 05 | H42: Folyamat | I42: Terv szerint | J42: Gyártás Iroda | K42: Műszaki tervezés | L42: Simon Kázmér | M42: Szántói Gábor | N42: 1 | O42: =_xlfn.XLOOKUP(Folyamat_Sor_Gyártáselőkészítés[[#This Row],[Feladat Rövidnév]],Feladat_Egység_idő1[Feladat Rövidnév],Feladat_Egység_idő1[Egység idő],0,0,1) -> 0.041666667 | P42: =_xlfn.XLOOKUP(Folyamat_Sor_Gyártáselőkészítés[[#This Row],[Feladat Rövidnév]],Feladat_Egység_idő1[Feladat Rövidnév],Feladat_Egység_idő1[Humánerő],0,0,1) -> 1 | Q42: =Folyamat_Sor_Gyártáselőkészítés[[#This Row],[DSMR]] & "-GyI-E.00" -> ProjektSzám-GyI-E.00 | R42: GyI-E.03 | S42: =Folyamat_Sor_Gyártáselőkészítés[[#This Row],[DSMR]] & "-" & Folyamat_Sor_Gyártáselőkészítés[[#This Row],[Szülő feladat Rővidnév]] -> ProjektSzám-GyI-E.03 | T42: SS | V42: 1
A43: =Projekt_Szám -> ProjektSzám | B43: GyI-E.05 | C43: =Folyamat_Sor_Gyártáselőkészítés[[#This Row],[DSMR]] & "-" & Folyamat_Sor_Gyártáselőkészítés[[#This Row],[Feladat Rövidnév]] -> ProjektSzám-GyI-E.05 | D43: =_xlfn.XLOOKUP(Folyamat_Sor_Gyártáselőkészítés[[#This Row],[Feladat Rövidnév]],Feladat_Egység_idő1[Feladat Rövidnév],Feladat_Egység_idő1[Feladat leírás],0,0,1) -> Meghajtón a mappa előkészítése | E43: =_xlfn.XLOOKUP(Folyamat_Sor_Gyártáselőkészítés[[#This Row],[Feladat Rövidnév]],Feladat_Egység_idő1[Feladat Rövidnév],Feladat_Egység_idő1[Feladat leírás],0,0,1) -> Meghajtón a mappa előkészítése | F43: =_xlfn.LET( _xlpm.megnevezés,"Előkészítés", IF(_xlpm.megnevezés=Folyamat_Sor_Gyártáselőkészítés[[#This Row],[Megnevezés]],"",_xlpm.megnevezés) ) -> Előkészítés | G43: 06 | H43: Folyamat | I43: Terv szerint | J43: Gyártás Iroda | K43: Műszaki tervezés | L43: Simon Kázmér | N43: 1 | O43: =_xlfn.XLOOKUP(Folyamat_Sor_Gyártáselőkészítés[[#This Row],[Feladat Rövidnév]],Feladat_Egység_idő1[Feladat Rövidnév],Feladat_Egység_idő1[Egység idő],0,0,1) -> 0.041666667 | P43: =_xlfn.XLOOKUP(Folyamat_Sor_Gyártáselőkészítés[[#This Row],[Feladat Rövidnév]],Feladat_Egység_idő1[Feladat Rövidnév],Feladat_Egység_idő1[Humánerő],0,0,1) -> 1 | Q43: =Folyamat_Sor_Gyártáselőkészítés[[#This Row],[DSMR]] & "-GyI-E.00" -> ProjektSzám-GyI-E.00 | R43: GyI-E.04 | S43: =Folyamat_Sor_Gyártáselőkészítés[[#This Row],[DSMR]] & "-" & Folyamat_Sor_Gyártáselőkészítés[[#This Row],[Szülő feladat Rővidnév]] -> ProjektSzám-GyI-E.04 | T43: SS | V43: 1
A44: =Projekt_Szám -> ProjektSzám | B44: GyI-E.06 | C44: =Folyamat_Sor_Gyártáselőkészítés[[#This Row],[DSMR]] & "-" & Folyamat_Sor_Gyártáselőkészítés[[#This Row],[Feladat Rövidnév]] -> ProjektSzám-GyI-E.06 | D44: =_xlfn.XLOOKUP(Folyamat_Sor_Gyártáselőkészítés[[#This Row],[Feladat Rövidnév]],Feladat_Egység_idő1[Feladat Rövidnév],Feladat_Egység_idő1[Feladat leírás],0,0,1) -> Kiíróba átvezetés | E44: =_xlfn.XLOOKUP(Folyamat_Sor_Gyártáselőkészítés[[#This Row],[Feladat Rövidnév]],Feladat_Egység_idő1[Feladat Rövidnév],Feladat_Egység_idő1[Feladat leírás],0,0,1) -> Kiíróba átvezetés | F44: =_xlfn.LET( _xlpm.megnevezés,"Előkészítés", IF(_xlpm.megnevezés=Folyamat_Sor_Gyártáselőkészítés[[#This Row],[Megnevezés]],"",_xlpm.megnevezés) ) -> Előkészítés | G44: 07 | H44: Folyamat | I44: Terv szerint | J44: Gyártás Iroda | K44: Műszaki tervezés | L44: Simon Kázmér | M44: Szántói Gábor | N44: 1 | O44: =_xlfn.XLOOKUP(Folyamat_Sor_Gyártáselőkészítés[[#This Row],[Feladat Rövidnév]],Feladat_Egység_idő1[Feladat Rövidnév],Feladat_Egység_idő1[Egység idő],0,0,1) -> 0.041666667 | P44: =_xlfn.XLOOKUP(Folyamat_Sor_Gyártáselőkészítés[[#This Row],[Feladat Rövidnév]],Feladat_Egység_idő1[Feladat Rövidnév],Feladat_Egység_idő1[Humánerő],0,0,1) -> 1 | Q44: =Folyamat_Sor_Gyártáselőkészítés[[#This Row],[DSMR]] & "-GyI-E.00" -> ProjektSzám-GyI-E.00 | R44: GyI-E.05 | S44: =Folyamat_Sor_Gyártáselőkészítés[[#This Row],[DSMR]] & "-" & Folyamat_Sor_Gyártáselőkészítés[[#This Row],[Szülő feladat Rővidnév]] -> ProjektSzám-GyI-E.05 | T44: SS | V44: 1
A45: =Projekt_Szám -> ProjektSzám | B45: GyI-E.07 | C45: =Folyamat_Sor_Gyártáselőkészítés[[#This Row],[DSMR]] & "-" & Folyamat_Sor_Gyártáselőkészítés[[#This Row],[Feladat Rövidnév]] -> ProjektSzám-GyI-E.07 | D45: =_xlfn.XLOOKUP(Folyamat_Sor_Gyártáselőkészítés[[#This Row],[Feladat Rövidnév]],Feladat_Egység_idő1[Feladat Rövidnév],Feladat_Egység_idő1[Feladat leírás],0,0,1) -> Kiíró elenőrzése | E45: =_xlfn.XLOOKUP(Folyamat_Sor_Gyártáselőkészítés[[#This Row],[Feladat Rövidnév]],Feladat_Egység_idő1[Feladat Rövidnév],Feladat_Egység_idő1[Feladat leírás],0,0,1) -> Kiíró elenőrzése | F45: =_xlfn.LET( _xlpm.megnevezés,"Előkészítés", IF(_xlpm.megnevezés=Folyamat_Sor_Gyártáselőkészítés[[#This Row],[Megnevezés]],"",_xlpm.megnevezés) ) -> Előkészítés | G45: 08 | H45: Folyamat | I45: Terv szerint | J45: Gyártás Iroda | K45: Műszaki tervezés | L45: Simon Kázmér | N45: 1 | O45: =_xlfn.XLOOKUP(Folyamat_Sor_Gyártáselőkészítés[[#This Row],[Feladat Rövidnév]],Feladat_Egység_idő1[Feladat Rövidnév],Feladat_Egység_idő1[Egység idő],0,0,1) -> 0.041666667 | P45: =_xlfn.XLOOKUP(Folyamat_Sor_Gyártáselőkészítés[[#This Row],[Feladat Rövidnév]],Feladat_Egység_idő1[Feladat Rövidnév],Feladat_Egység_idő1[Humánerő],0,0,1) -> 1 | Q45: =Folyamat_Sor_Gyártáselőkészítés[[#This Row],[DSMR]] & "-GyI-E.00" -> ProjektSzám-GyI-E.00 | R45: GyI-E.06 | S45: =Folyamat_Sor_Gyártáselőkészítés[[#This Row],[DSMR]] & "-" & Folyamat_Sor_Gyártáselőkészítés[[#This Row],[Szülő feladat Rővidnév]] -> ProjektSzám-GyI-E.06 | T45: FS | V45: 1
A46: =Projekt_Szám -> ProjektSzám | B46: GyI-E.08 | C46: =Folyamat_Sor_Gyártáselőkészítés[[#This Row],[DSMR]] & "-" & Folyamat_Sor_Gyártáselőkészítés[[#This Row],[Feladat Rövidnév]] -> ProjektSzám-GyI-E.08 | D46: =_xlfn.XLOOKUP(Folyamat_Sor_Gyártáselőkészítés[[#This Row],[Feladat Rövidnév]],Feladat_Egység_idő1[Feladat Rövidnév],Feladat_Egység_idő1[Feladat leírás],0,0,1) -> Gyártás inditó megbeszéléssel | E46: =_xlfn.XLOOKUP(Folyamat_Sor_Gyártáselőkészítés[[#This Row],[Feladat Rövidnév]],Feladat_Egység_idő1[Feladat Rövidnév],Feladat_Egység_idő1[Feladat leírás],0,0,1) -> Gyártás inditó megbeszéléssel | F46: =_xlfn.LET( _xlpm.megnevezés,"Előkészítés", IF(_xlpm.megnevezés=Folyamat_Sor_Gyártáselőkészítés[[#This Row],[Megnevezés]],"",_xlpm.megnevezés) ) -> Előkészítés | G46: 09 | H46: Folyamat | I46: Terv szerint | J46: Gyártás Iroda | K46: Műszaki tervezés | L46: Simon Kázmér | N46: 1 | O46: =_xlfn.XLOOKUP(Folyamat_Sor_Gyártáselőkészítés[[#This Row],[Feladat Rövidnév]],Feladat_Egység_idő1[Feladat Rövidnév],Feladat_Egység_idő1[Egység idő],0,0,1) -> 0.041666667 | P46: =_xlfn.XLOOKUP(Folyamat_Sor_Gyártáselőkészítés[[#This Row],[Feladat Rövidnév]],Feladat_Egység_idő1[Feladat Rövidnév],Feladat_Egység_idő1[Humánerő],0,0,1) -> 1 | Q46: =Folyamat_Sor_Gyártáselőkészítés[[#This Row],[DSMR]] & "-GyI-E.00" -> ProjektSzám-GyI-E.00 | R46: GyI-E.07 | S46: =Folyamat_Sor_Gyártáselőkészítés[[#This Row],[DSMR]] & "-" & Folyamat_Sor_Gyártáselőkészítés[[#This Row],[Szülő feladat Rővidnév]] -> ProjektSzám-GyI-E.07 | T46: FS | V46: 1
A47: =Projekt_Szám -> ProjektSzám | B47: GyI-E.08.01 | C47: =Folyamat_Sor_Gyártáselőkészítés[[#This Row],[DSMR]] & "-" & Folyamat_Sor_Gyártáselőkészítés[[#This Row],[Feladat Rövidnév]] -> ProjektSzám-GyI-E.08.01 | D47: =_xlfn.XLOOKUP(Folyamat_Sor_Gyártáselőkészítés[[#This Row],[Feladat Rövidnév]],Feladat_Egység_idő1[Feladat Rövidnév],Feladat_Egység_idő1[Feladat leírás],0,0,1) -> 0 | E47: =_xlfn.XLOOKUP(Folyamat_Sor_Gyártáselőkészítés[[#This Row],[Feladat Rövidnév]],Feladat_Egység_idő1[Feladat Rövidnév],Feladat_Egység_idő1[Feladat leírás],0,0,1) -> 0 | F47: =_xlfn.LET( _xlpm.megnevezés,"Előkészítés", IF(_xlpm.megnevezés=Folyamat_Sor_Gyártáselőkészítés[[#This Row],[Megnevezés]],"",_xlpm.megnevezés) ) -> Előkészítés | G47: 10 | H47: Folyamat | I47: Terv szerint | J47: Gyártás Iroda | K47: Műszaki tervezés | L47: Simon Kázmér | N47: 1 | O47: =_xlfn.XLOOKUP(Folyamat_Sor_Gyártáselőkészítés[[#This Row],[Feladat Rövidnév]],Feladat_Egység_idő1[Feladat Rövidnév],Feladat_Egység_idő1[Egység idő],0,0,1) -> 0 | P47: =_xlfn.XLOOKUP(Folyamat_Sor_Gyártáselőkészítés[[#This Row],[Feladat Rövidnév]],Feladat_Egység_idő1[Feladat Rövidnév],Feladat_Egység_idő1[Humánerő],0,0,1) -> 0 | Q47: =Folyamat_Sor_Gyártáselőkészítés[[#This Row],[DSMR]] & "-GyI-E.00" -> ProjektSzám-GyI-E.00 | R47: GyI-E.08 | S47: =Folyamat_Sor_Gyártáselőkészítés[[#This Row],[DSMR]] & "-" & Folyamat_Sor_Gyártáselőkészítés[[#This Row],[Szülő feladat Rővidnév]] -> ProjektSzám-GyI-E.08 | T47: SS | V47: 1
A48: =Projekt_Szám -> ProjektSzám | B48: GyI-E.09 | C48: =Folyamat_Sor_Gyártáselőkészítés[[#This Row],[DSMR]] & "-" & Folyamat_Sor_Gyártáselőkészítés[[#This Row],[Feladat Rövidnév]] -> ProjektSzám-GyI-E.09 | D48: =_xlfn.XLOOKUP(Folyamat_Sor_Gyártáselőkészítés[[#This Row],[Feladat Rövidnév]],Feladat_Egység_idő1[Feladat Rövidnév],Feladat_Egység_idő1[Feladat leírás],0,0,1) -> Anyagszükséglet | E48: =_xlfn.XLOOKUP(Folyamat_Sor_Gyártáselőkészítés[[#This Row],[Feladat Rövidnév]],Feladat_Egység_idő1[Feladat Rövidnév],Feladat_Egység_idő1[Feladat leírás],0,0,1) -> Anyagszükséglet | F48: =_xlfn.LET( _xlpm.megnevezés,"Előkészítés", IF(_xlpm.megnevezés=Folyamat_Sor_Gyártáselőkészítés[[#This Row],[Megnevezés]],"",_xlpm.megnevezés) ) -> Előkészítés | G48: 11 | H48: Folyamat | I48: Terv szerint | J48: Gyártás Iroda | K48: Műszaki tervezés | L48: Simon Kázmér | N48: 1 | O48: =_xlfn.XLOOKUP(Folyamat_Sor_Gyártáselőkészítés[[#This Row],[Feladat Rövidnév]],Feladat_Egység_idő1[Feladat Rövidnév],Feladat_Egység_idő1[Egység idő],0,0,1) -> 0.041666667 | P48: =_xlfn.XLOOKUP(Folyamat_Sor_Gyártáselőkészítés[[#This Row],[Feladat Rövidnév]],Feladat_Egység_idő1[Feladat Rövidnév],Feladat_Egység_idő1[Humánerő],0,0,1) -> 1 | Q48: =Folyamat_Sor_Gyártáselőkészítés[[#This Row],[DSMR]] & "-GyI-E.00" -> ProjektSzám-GyI-E.00 | R48: GyI-E.08.01 | S48: =Folyamat_Sor_Gyártáselőkészítés[[#This Row],[DSMR]] & "-" & Folyamat_Sor_Gyártáselőkészítés[[#This Row],[Szülő feladat Rővidnév]] -> ProjektSzám-GyI-E.08.01 | T48: FS | V48: 1
B50: Termékek Tipus
B51: Tokba
B52: Tokban Ajtólap
...

Sheet Folyamatok
A4: DSMR | B4: Feladat Rövidnév | C4: Feladat ID | D4: Feladat leírás | E4: Megnevezés | F4: Főfeladat Megnevezése | G4: Sorszám | H4: Feladat Tipus | I4: Kockázat | J4: Részleg 02 | K4: Részleg 01 | L4: Felelős | M4: Támogató | N4: Volumen | O4: Egység idő | P4: Humánerő | Q4: Ősszefoglaló feladat ID | R4: Szülő feladat Rővidnév | S4: Szülő feladat ID | T4: Feladat Függöség Tipusa | U4: Feladat Késleltetés | V4: Feladat Elinditása Részleges készültség esetén | W4: Extra nap
A5: ProjektSzám | B5: GyI-E.00 | C5: ProjektSzám-GyI-E.00 | D5: Előkészítés | E5: Előkészítés | G5: 00 | H5: Összetett folyamat | I5: Terv szerint | J5: Gyártás Iroda | N5: 1 | O5: 0 | P5: 0 | V5: 1 | W5: 5
A6: ProjektSzám | B6: GyI-E.01 | C6: ProjektSzám-GyI-E.01 | D6: Megrendelés átadó megbeszélés | E6: Megrendelés átadó megbeszélés | F6: Előkészítés | G6: 01 | H6: Folyamat | I6: Terv szerint | J6: Gyártás Iroda | K6: Műszaki tervezés | L6: Simon Kázmér | N6: 1 | O6: 0.041666667 | P6: 1 | Q6: ProjektSzám-GyI-E.00 | R6: GyI-E.00 | S6: ProjektSzám-GyI-E.00 | T6: SS | V6: 1
A7: ProjektSzám | B7: GyI-E.02 | C7: ProjektSzám-GyI-E.02 | D7: Információk beszerzése | E7: Információk beszerzése | F7: Előkészítés | G7: 02 | H7: Folyamat | I7: Terv szerint | J7: Gyártás Iroda | K7: Műszaki tervezés | L7: Simon Kázmér | N7: 1 | O7: 0.041666667 | P7: 1 | Q7: ProjektSzám-GyI-E.00 | R7: GyI-E.01 | S7: ProjektSzám-GyI-E.01 | T7: SS | V7: 1
A8: ProjektSzám | B8: GyI-E.02.01 | C8: ProjektSzám-GyI-E.02.01 | D8: 0 | E8: 0 | F8: Előkészítés | G8: 03 | H8: Folyamat | I8: Terv szerint | J8: Gyártás Iroda | K8: Műszaki tervezés | L8: Simon Kázmér | M8: Szántói Gábor | N8: 1 | O8: 0 | P8: 0 | Q8: ProjektSzám-GyI-E.00 | R8: GyI-E.02 | S8: ProjektSzám-GyI-E.02 | T8: FS | V8: 1
A9: ProjektSzám | B9: GyI-E.03 | C9: ProjektSzám-GyI-E.03 | D9: Megerndelőlap elenőrzése | E9: Megerndelőlap elenőrzése | F9: Előkészítés | G9: 04 | H9: Folyamat | I9: Terv szerint | J9: Gyártás Iroda | K9: Műszaki tervezés | L9: Simon Kázmér | N9: 1 | O9: 0.041666667 | P9: 1 | Q9: ProjektSzám-GyI-E.00 | R9: GyI-E.02.01 | S9: ProjektSzám-GyI-E.02.01 | T9: SS | V9: 1
A10: ProjektSzám | B10: GyI-E.04 | C10: ProjektSzám-GyI-E.04 | D10: Információk elenőrzése | E10: Információk elenőrzése | F10: Előkészítés | G10: 05 | H10: Folyamat | I10: Terv szerint | J10: Gyártás Iroda | K10: Műszaki tervezés | L10: Simon Kázmér | M10: Szántói Gábor | N10: 1 | O10: 0.041666667 | P10: 1 | Q10: ProjektSzám-GyI-E.00 | R10: GyI-E.03 | S10: ProjektSzám-GyI-E.03 | T10: SS | V10: 1
A11: ProjektSzám | B11: GyI-E.05 | C11: ProjektSzám-GyI-E.05 | D11: Meghajtón a mappa előkészítése | E11: Meghajtón a mappa előkészítése | F11: Előkészítés | G11: 06 | H11: Folyamat | I11: Terv szerint | J11: Gyártás Iroda | K11: Műszaki tervezés | L11: Simon Kázmér | N11: 1 | O11: 0.041666667 | P11: 1 | Q11: ProjektSzám-GyI-E.00 | R11: GyI-E.04 | S11: ProjektSzám-GyI-E.04 | T11: SS | V11: 1
A12: ProjektSzám | B12: GyI-E.06 | C12: ProjektSzám-GyI-E.06 | D12: Kiíróba átvezetés | E12: Kiíróba átvezetés | F12: Előkészítés | G12: 07 | H12: Folyamat | I12: Terv szerint | J12: Gyártás Iroda | K12: Műszaki tervezés | L12: Simon Kázmér | M12: Szántói Gábor | N12: 1 | O12: 0.041666667 | P12: 1 | Q12: ProjektSzám-GyI-E.00 | R12: GyI-E.05 | S12: ProjektSzám-GyI-E.05 | T12: SS | V12: 1
A13: ProjektSzám | B13: GyI-E.07 | C13: ProjektSzám-GyI-E.07 | D13: Kiíró elenőrzése | E13: Kiíró elenőrzése | F13: Előkészítés | G13: 08 | H13: Folyamat | I13: Terv szerint | J13: Gyártás Iroda | K13: Műszaki tervezés | L13: Simon Kázmér | N13: 1 | O13: 0.041666667 | P13: 1 | Q13: ProjektSzám-GyI-E.00 | R13: GyI-E.06 | S13: ProjektSzám-GyI-E.06 | T13: FS | V13: 1
A14: ProjektSzám | B14: GyI-E.08 | C14: ProjektSzám-GyI-E.08 | D14: Gyártás inditó megbeszéléssel | E14: Gyártás inditó megbeszéléssel | F14: Előkészítés | G14: 09 | H14: Folyamat | I14: Terv szerint | J14: Gyártás Iroda | K14: Műszaki tervezés | L14: Simon Kázmér | N14: 1 | O14: 0.041666667 | P14: 1 | Q14: ProjektSzám-GyI-E.00 | R14: GyI-E.07 | S14: ProjektSzám-GyI-E.07 | T14: FS | V14: 1
A15: ProjektSzám | B15: GyI-E.08.01 | C15: ProjektSzám-GyI-E.08.01 | D15: 0 | E15: 0 | F15: Előkészítés | G15: 10 | H15: Folyamat | I15: Terv szerint | J15: Gyártás Iroda | K15: Műszaki tervezés | L15: Simon Kázmér | N15: 1 | O15: 0 | P15: 0 | Q15: ProjektSzám-GyI-E.00 | R15: GyI-E.08 | S15: ProjektSzám-GyI-E.08 | T15: SS | V15: 1
A16: ProjektSzám | B16: GyI-E.09 | C16: ProjektSzám-GyI-E.09 | D16: Anyagszükséglet | E16: Anyagszükséglet | F16: Előkészítés | G16: 11 | H16: Folyamat | I16: Terv szerint | J16: Gyártás Iroda | K16: Műszaki tervezés | L16: Simon Kázmér | N16: 1 | O16: 0.041666667 | P16: 1 | Q16: ProjektSzám-GyI-E.00 | R16: GyI-E.08.01 | S16: ProjektSzám-GyI-E.08.01 | T16: FS | V16: 1
A17: ProjektSzám | B17: GyV-BF.00 | C17: ProjektSzám-GyV-BF.00 | D17: Bútorfront | E17: Bútorfront | G17: 00 | H17: Összetett folyamat | I17: Terv szerint | J17: Gyártásvezetés | L17: Martin Zoltán | N17: 1 | O17: 0 | P17: 0 | R17: GyI-E.00 | S17: ProjektSzám-GyI-E.00 | T17: FS | U17: 4 | V17: 1 | W17: 9
A18: ProjektSzám | B18: GyV-BF.01 | C18: ProjektSzám-GyV-BF.01 | D18: 18-as szabás | E18: 18-as szabás | F18: Bútorfront | G18: 01 | H18: Folyamat | I18: Terv szerint | J18: Gyártásvezetés | K18: Asztalos | L18: Geröcs István | M18: Berei János | N18: 70 | O18: 0.0030555556 | P18: 2 | Q18: ProjektSzám-GyV-BF.00 | R18: GyV-BF.00 | S18: ProjektSzám-GyV-BF.00 | T18: SS | V18: 1
A19: ProjektSzám | B19: GyV-BF.02 | C19: ProjektSzám-GyV-BF.02 | D19: CNC kontúr+ minta | E19: CNC kontúr+ minta | F19: Bútorfront | G19: 02 | H19: Folyamat | I19: Terv szerint | J19: Gyártásvezetés | K19: CNC | L19: Dancsik János | N19: 70 | O19: 0.0094212963 | P19: 1 | Q19: ProjektSzám-GyV-BF.00 | R19: GyV-BF.01 | S19: ProjektSzám-GyV-BF.01 | T19: FS | V19: 1
A20: ProjektSzám | B20: GyV-BF.03 | C20: ProjektSzám-GyV-BF.03 | D20: Csiszolás | E20: Csiszolás | F20: Bútorfront | G20: 03 | H20: Folyamat | I20: Terv szerint | J20: Gyártásvezetés | K20: Összeszerelő | N20: 70 | O20: 0.0094212963 | P20: 1 | Q20: ProjektSzám-GyV-BF.00 | R20: GyV-BF.02 | S20: ProjektSzám-GyV-BF.02 | T20: FS | V20: 1
A21: ProjektSzám | B21: GyV-BF.04 | C21: ProjektSzám-GyV-BF.04 | D21: Fújás | E21: Fújás | F21: Bútorfront | G21: 04 | H21: Folyamat | I21: Terv szerint | J21: Gyártásvezetés | K21: Összeszerelő | N21: 70 | O21: 0.0025 | P21: 1 | Q21: ProjektSzám-GyV-BF.00 | R21: GyV-BF.03 | S21: ProjektSzám-GyV-BF.03 | T21: SS | V21: 1
A22: ProjektSzám | B22: GyV-BF.05 | C22: ProjektSzám-GyV-BF.05 | D22: Ragasztó Csiszolás | E22: Ragasztó Csiszolás | F22: Bútorfront | G22: 05 | H22: Folyamat | I22: Terv szerint | J22: Gyártásvezetés | K22: Fóliázó | L22: Martin Zoltán | N22: 3 | O22: 0.0032638889 | P22: 1 | Q22: ProjektSzám-GyV-BF.00 | R22: GyV-BF.04 | S22: ProjektSzám-GyV-BF.04 | T22: FS | V22: 1
A23: ProjektSzám | B23: GyV-BF.06 | C23: ProjektSzám-GyV-BF.06 | D23: Fóliázás | E23: Fóliázás | F23: Bútorfront | G23: 06 | H23: Folyamat | I23: Terv szerint | J23: Gyártásvezetés | K23: Fóliázó | L23: Martin Zoltán | N23: 3 | O23: 0.0072916667 | P23: 2 | Q23: ProjektSzám-GyV-BF.00 | R23: GyV-BF.05 | S23: ProjektSzám-GyV-BF.05 | T23: SS | V23: 1
A24: ProjektSzám | B24: GyV-BF.07 | C24: ProjektSzám-GyV-BF.07 | D24: Kivágás | E24: Kivágás | F24: Bútorfront | G24: 07 | H24: Folyamat | I24: Terv szerint | J24: Gyártásvezetés | K24: Fóliázó | L24: Martin Zoltán | N24: 3 | O24: 0.0026041667 | P24: 1 | Q24: ProjektSzám-GyV-BF.00 | R24: GyV-BF.05 | S24: ProjektSzám-GyV-BF.05 | T24: SS | V24: 1
A25: ProjektSzám | B25: GyV-BF.08 | C25: ProjektSzám-GyV-BF.08 | D25: Visszafordítás | E25: Visszafordítás | F25: Bútorfront | G25: 08 | H25: Folyamat | I25: Terv szerint | J25: Gyártásvezetés | K25: Fóliázó | L25: Martin Zoltán | N25: 3 | O25: 0.0069444444 | P25: 1 | Q25: ProjektSzám-GyV-BF.00 | R25: GyV-BF.05 | S25: ProjektSzám-GyV-BF.05 | T25: SS | V25: 1
A26: ProjektSzám | B26: GyV-BF.09 | C26: ProjektSzám-GyV-BF.09 | D26: Festőnél | E26: Festőnél | F26: Bútorfront | G26: 09 | H26: Folyamat | I26: Terv szerint | J26: Gyártásvezetés | K26: CNC | L26: Dancsik János | N26: 70 | O26: 0.041666667 | P26: 1 | Q26: ProjektSzám-GyV-BF.00 | R26: GyV-BF.08 | S26: ProjektSzám-GyV-BF.08 | T26: FS | V26: 1
A27: ProjektSzám | B27: GyV-BF.10 | C27: ProjektSzám-GyV-BF.10 | D27: Festőtöl viszahozzva | E27: Festőtöl viszahozzva | F27: Bútorfront | G27: 10 | H27: Folyamat | I27: Terv szerint | J27: Gyártásvezetés | K27: Összeszerelő | N27: 70 | O27: 0.041666667 | P27: 1 | Q27: ProjektSzám-GyV-BF.00 | R27: GyV-BF.09 | S27: ProjektSzám-GyV-BF.09 | T27: FS | V27: 1

Sheet Folyamatok tervezése
C1: Start date: | D1: =INDEX(Projekt_Data[Start Date],1) -> 45823 | E1: Deadline: | F1: =INDEX(Projekt_Data[Dedline],1) -> 45840 | AB1: 0
C2: Hetek | D2: 3 | E2: Nap | F2: 2
A4: Projekt azonosító | B4: Feladat Rövidnév | C4: Feladat ID | D4: Feladat leírás | E4: Feladat Tipus | F4: Kockázat | G4: Részleg 02 | H4: Részleg 01 | I4: Felelős | J4: Támogató | K4: Készültség | L4: Prioritás | M4: Volumen | N4: Egység idő | O4: Humánerő | P4: Ősszefoglaló feladat ID | Q4: Szülő feladat ID | R4: Feladat Függöség Tipusa | S4: Feladat Késleltetés | T4: Fix kexdés | U4: Feladat Elinditása Részleges készültség esetén | V4: Részleges Kezdés | W4: Függökezdés Kalkulált | X4: Függökezdés késleltetett | Y4: Függökezdés késleltetett plusz | Z4: Függökezdés | AA4: Kalkulált kezdés | AB4: Kezdés | AC4: Tényleges Kezdés | AD4: Tervezettidő | AE4: Tervezett Munkaidő | AF4: Extra nap | AG4: Napok száma | AH4: Nem munkanap | AI4: Fixbefejezés | AJ4: Függöbefejezés | AK4: Kalkulált befejezés | AL4: Kalkulált befejezés2 | AM4: Befejezés | AN4: Tényleges befejezés
A5: =IFERROR(Folyamat[[#This Row],[DSMR]],"") -> ProjektSzám | B5: =IFERROR(Folyamat[[#This Row],[Feladat Rövidnév]],"") -> GyI-E.00 | C5: =IFERROR(Mérföldkövek[[#This Row],[Projekt azonosító]] & "-" & Mérföldkövek[[#This Row],[Feladat Rövidnév]],"") -> ProjektSzám-GyI-E.00 | D5: =IFERROR(Folyamat[[#This Row],[Feladat leírás]],"") -> Előkészítés | E5: =IFERROR(Folyamat[[#This Row],[Feladat Tipus]],"") -> Összetett folyamat | F5: =IFERROR(Folyamat[[#This Row],[Kockázat]],"") -> Terv szerint | G5: =IFERROR(Folyamat[[#This Row],[Részleg 02]],"") -> Gyártás Iroda | H5: =IFERROR(Folyamat[[#This Row],[Részleg 01]],"") -> 0 | I5: =IFERROR(Folyamat[[#This Row],[Felelős]],"") -> 0 | J5: =IFERROR(Folyamat[[#This Row],[Támogató]],"") -> 0 | K5: 0 | M5: =IFERROR(Folyamat[[#This Row],[Volumen]],"") -> 1 | N5: =IFERROR(Folyamat[[#This Row],[Egység idő]],"") -> 0 | O5: =IFERROR(Folyamat[[#This Row],[Humánerő]],"") -> 0 | P5: =IFERROR(IF(Folyamat[[#This Row],[Ősszefoglaló feladat ID]]=0,"",Folyamat[[#This Row],[Ősszefoglaló feladat ID]]),"") | Q5: =IFERROR(IF(Folyamat[[#This Row],[Szülő feladat ID]]=0,"",Folyamat[[#This Row],[Szülő feladat ID]]),"") | R5: =IFERROR(IF(Folyamat[[#This Row],[Feladat Függöség Tipusa]]=0,"",Folyamat[[#This Row],[Feladat Függöség Tipusa]]),"") | S5: =IFERROR(Folyamat[[#This Row],[Feladat Késleltetés]],"") -> 0 | T5: =$D$1 -> 45823 | U5: =IFERROR(Folyamat[[#This Row],[Feladat Elinditása Részleges készültség esetén]],"") -> 1 | V5: =IF(Mérföldkövek[[#This Row],[Szülő feladat ID]]<>"",IF(AND(Mérföldkövek[[#This Row],[Feladat Elinditása Részleges készültség esetén]]<=_xlfn.XLOOKUP(Mérföldkövek[[#This Row],[Szülő feladat ID]],Mérföldkövek[Feladat ID],Mérföldkövek[Készültség]),TODAY()<_xlfn.XLOOKUP(Mérföldkövek[[#This Row],[Szülő feladat ID]],Mérföldkövek[Feladat ID],Mérföldkövek[Befejezés])),TODAY(),0),0) -> 0 | W5: {=IF(AND(Mérföldkövek[[#This Row],[Szülő feladat ID]]<>"",Mérföldkövek[[#This Row],[Feladat Függöség Tipusa]]<>""),_xlfn.IFS(Mérföldkövek[[#This Row],[Feladat Függöség Tipusa]]="FS",_xlfn.XLOOKUP(Mérföldkövek[[#This Row],[Szülő feladat ID]],Mérföldkövek[Feladat ID],Mérföldkövek[Befejezés]+1),Mérföldkövek[[#This Row],[Feladat Függöség Tipusa]]="SS",_xlfn.XLOOKUP(Mérföldkövek[[#This Row],[Szülő feladat ID]],Mérföldkövek[Feladat ID],Mérföldkövek[Kezdés]),TRUE,0),0)} -> 0 | X5: =Mérföldkövek[[#This Row],[Függökezdés Kalkulált]]+Mérföldkövek[[#This Row],[Feladat Késleltetés]] -> 0 | Y5: =IF(Mérföldkövek[[#This Row],[Feladat Késleltetés]] = 0,0,IF(Mérföldkövek[[#This Row],[Feladat Késleltetés]]>(NETWORKDAYS(Mérföldkövek[[#This Row],[Függökezdés Kalkulált]],Mérföldkövek[[#This Row],[Függökezdés késleltetett]])-1),Mérföldkövek[[#This Row],[Feladat Késleltetés]]-(NETWORKDAYS(Mérföldkövek[[#This Row],[Függökezdés Kalkulált]],Mérföldkövek[[#This Row],[Függökezdés késleltetett]])-1))) -> 0 | Z5: =IF(OR(WEEKDAY(Mérföldkövek[[#This Row],[Függökezdés Kalkulált]],2)>5), WORKDAY(Mérföldkövek[[#This Row],[Függökezdés Kalkulált]],1), Mérföldkövek[[#This Row],[Függökezdés Kalkulált]]) + Mérföldkövek[[#This Row],[Függökezdés késleltetett plusz]] -> 2 | AA5: {=_xlfn.IFS(Mérföldkövek[[#This Row],[Fix kexdés]]<>0,Mérföldkövek[[#This Row],[Fix kexdés]],Mérföldkövek[[#This Row],[Részleges Kezdés]]<>0,Mérföldkövek[[#This Row],[Részleges Kezdés]],Mérföldkövek[[#This Row],[Függökezdés]]<>0,Mérföldkövek[[#This Row],[Függökezdés]],TRUE,0)} -> 45823 | AB5: =IF(Mérföldkövek[[#This Row],[Volumen]]<=0,0,IF(OR(WEEKDAY(Mérföldkövek[[#This Row],[Kalkulált kezdés]],2)>5), WORKDAY(Mérföldkövek[[#This Row],[Kalkulált kezdés]],1), Mérföldkövek[[#This Row],[Kalkulált kezdés]])) -> 45824 | AD5: =IF(AND(Mérföldkövek[[#This Row],[Volumen]]<>0,Mérföldkövek[[#This Row],[Volumen]]<>"",Mérföldkövek[[#This Row],[Egység idő]]<>0,Mérföldkövek[[#This Row],[Egység idő]]<>""),Mérföldkövek[[#This Row],[Volumen]]*Mérföldkövek[[#This Row],[Egység idő]],0) -> 0 | AE5: =IF(AND(Mérföldkövek[[#This Row],[Volumen]]<>0,Mérföldkövek[[#This Row],[Volumen]]<>"",Mérföldkövek[[#This Row],[Egység idő]]<>0,Mérföldkövek[[#This Row],[Egység idő]]<>""),Mérföldkövek[[#This Row],[Volumen]]*Mérföldkövek[[#This Row],[Egység idő]]*Mérföldkövek[[#This Row],[Humánerő]],0) -> 0 | AF5: =IFERROR(Folyamat[[#This Row],[Extra nap]],"") -> 5 | AG5: =ROUNDUP((Mérföldkövek[[#This Row],[Tervezettidő]]*24)/8,0)+Mérföldkövek[[#This Row],[Extra nap]] -> 5 | AH5: =IF(OR(Mérföldkövek[[#This Row],[Kezdés]]<4000,Mérföldkövek[[#This Row],[Napok száma]]=""),0,ROUNDUP((Mérföldkövek[[#This Row],[Napok száma]]-NETWORKDAYS(Mérföldkövek[[#This Row],[Kezdés]],Mérföldkövek[[#This Row],[Kezdés]]+Mérföldkövek[[#This Row],[Napok száma]]-1,0))/2,0)*2) -> 0 | AJ5: {=IF(AND(Mérföldkövek[[#This Row],[Szülő feladat ID]]<>"",Mérföldkövek[[#This Row],[Feladat Függöség Tipusa]]<>""),_xlfn.IFS(Mérföldkövek[[#This Row],[Feladat Függöség Tipusa]]="FF",_xlfn.XLOOKUP(Mérföldkövek[[#This Row],[Szülő feladat ID]],Mérföldkövek[Feladat ID],Mérföldkövek[Befejezés]),Mérföldkövek[[#This Row],[Feladat Függöség Tipusa]]="SF",_xlfn.XLOOKUP(Mérföldkövek[[#This Row],[Szülő feladat ID]],Mérföldkövek[Feladat ID],Mérföldkövek[Kezdés]),TRUE,0),0)} -> 0 | AK5: =IF(OR(Mérföldkövek[[#This Row],[Kezdés]]=0,Mérföldkövek[[#This Row],[Napok száma]]=0),0,Mérföldkövek[[#This Row],[Kezdés]]+Mérföldkövek[[#This Row],[Napok száma]]-1+Mérföldkövek[[#This Row],[Nem munkanap]]) -> 45828 | AL5: {=_xlfn.IFS(Mérföldkövek[[#This Row],[Fixbefejezés]]<>0,Mérföldkövek[[#This Row],[Fixbefejezés]],Mérföldkövek[[#This Row],[Függöbefejezés]]<>0,Mérföldkövek[[#This Row],[Függöbefejezés]],Mérföldkövek[[#This Row],[Kalkulált befejezés]]<>0,Mérföldkövek[[#This Row],[Kalkulált befejezés]],TRUE,0)} -> 45828 | AM5: =IF(OR(WEEKDAY(Mérföldkövek[[#This Row],[Kalkulált befejezés2]],2)>5), WORKDAY(Mérföldkövek[[#This Row],[Kalkulált befejezés2]],1), Mérföldkövek[[#This Row],[Kalkulált befejezés2]]) -> 45828
A6: =IFERROR(Folyamat[[#This Row],[DSMR]],"") -> ProjektSzám | B6: =IFERROR(Folyamat[[#This Row],[Feladat Rövidnév]],"") -> GyI-E.01 | C6: =IFERROR(Mérföldkövek[[#This Row],[Projekt azonosító]] & "-" & Mérföldkövek[[#This Row],[Feladat Rövidnév]],"") -> ProjektSzám-GyI-E.01 | D6: =IFERROR(Folyamat[[#This Row],[Feladat leírás]],"") -> Megrendelés átadó megbeszélés | E6: =IFERROR(Folyamat[[#This Row],[Feladat Tipus]],"") -> Folyamat | F6: =IFERROR(Folyamat[[#This Row],[Kockázat]],"") -> Terv szerint | G6: =IFERROR(Folyamat[[#This Row],[Részleg 02]],"") -> Gyártás Iroda | H6: =IFERROR(Folyamat[[#This Row],[Részleg 01]],"") -> Műszaki tervezés | I6: =IFERROR(Folyamat[[#This Row],[Felelős]],"") -> Simon Kázmér | J6: =IFERROR(Folyamat[[#This Row],[Támogató]],"") -> 0 | K6: 0 | M6: =IFERROR(Folyamat[[#This Row],[Volumen]],"") -> 1 | N6: =IFERROR(Folyamat[[#This Row],[Egység idő]],"") -> 0.041666667 | O6: =IFERROR(Folyamat[[#This Row],[Humánerő]],"") -> 1 | P6: =IFERROR(IF(Folyamat[[#This Row],[Ősszefoglaló feladat ID]]=0,"",Folyamat[[#This Row],[Ősszefoglaló feladat ID]]),"") -> ProjektSzám-GyI-E.00 | Q6: =IFERROR(IF(Folyamat[[#This Row],[Szülő feladat ID]]=0,"",Folyamat[[#This Row],[Szülő feladat ID]]),"") -> ProjektSzám-GyI-E.00 | R6: =IFERROR(IF(Folyamat[[#This Row],[Feladat Függöség Tipusa]]=0,"",Folyamat[[#This Row],[Feladat Függöség Tipusa]]),"") -> SS | S6: =IFERROR(Folyamat[[#This Row],[Feladat Késleltetés]],"") -> 0 | U6: =IFERROR(Folyamat[[#This Row],[Feladat Elinditása Részleges készültség esetén]],"") -> 1 | V6: =IF(Mérföldkövek[[#This Row],[Szülő feladat ID]]<>"",IF(AND(Mérföldkövek[[#This Row],[Feladat Elinditása Részleges készültség esetén]]<=_xlfn.XLOOKUP(Mérföldkövek[[#This Row],[Szülő feladat ID]],Mérföldkövek[Feladat ID],Mérföldkövek[Készültség]),TODAY()<_xlfn.XLOOKUP(Mérföldkövek[[#This Row],[Szülő feladat ID]],Mérföldkövek[Feladat ID],Mérföldkövek[Befejezés])),TODAY(),0),0) -> 0 | W6: {=IF(AND(Mérföldkövek[[#This Row],[Szülő feladat ID]]<>"",Mérföldkövek[[#This Row],[Feladat Függöség Tipusa]]<>""),_xlfn.IFS(Mérföldkövek[[#This Row],[Feladat Függöség Tipusa]]="FS",_xlfn.XLOOKUP(Mérföldkövek[[#This Row],[Szülő feladat ID]],Mérföldkövek[Feladat ID],Mérföldkövek[Befejezés]+1),Mérföldkövek[[#This Row],[Feladat Függöség Tipusa]]="SS",_xlfn.XLOOKUP(Mérföldkövek[[#This Row],[Szülő feladat ID]],Mérföldkövek[Feladat ID],Mérföldkövek[Kezdés]),TRUE,0),0)} -> 45824 | X6: =Mérföldkövek[[#This Row],[Függökezdés Kalkulált]]+Mérföldkövek[[#This Row],[Feladat Késleltetés]] -> 45824 | Y6: =IF(Mérföldkövek[[#This Row],[Feladat Késleltetés]] = 0,0,IF(Mérföldkövek[[#This Row],[Feladat Késleltetés]]>(NETWORKDAYS(Mérföldkövek[[#This Row],[Függökezdés Kalkulált]],Mérföldkövek[[#This Row],[Függökezdés késleltetett]])-1),Mérföldkövek[[#This Row],[Feladat Késleltetés]]-(NETWORKDAYS(Mérföldkövek[[#This Row],[Függökezdés Kalkulált]],Mérföldkövek[[#This Row],[Függökezdés késleltetett]])-1))) -> 0 | Z6: =IF(OR(WEEKDAY(Mérföldkövek[[#This Row],[Függökezdés Kalkulált]],2)>5), WORKDAY(Mérföldkövek[[#This Row],[Függökezdés Kalkulált]],1), Mérföldkövek[[#This Row],[Függökezdés Kalkulált]]) + Mérföldkövek[[#This Row],[Függökezdés késleltetett plusz]] -> 45824 | AA6: {=_xlfn.IFS(Mérföldkövek[[#This Row],[Fix kexdés]]<>0,Mérföldkövek[[#This Row],[Fix kexdés]],Mérföldkövek[[#This Row],[Részleges Kezdés]]<>0,Mérföldkövek[[#This Row],[Részleges Kezdés]],Mérföldkövek[[#This Row],[Függökezdés]]<>0,Mérföldkövek[[#This Row],[Függökezdés]],TRUE,0)} -> 45824 | AB6: =IF(Mérföldkövek[[#This Row],[Volumen]]<=0,0,IF(OR(WEEKDAY(Mérföldkövek[[#This Row],[Kalkulált kezdés]],2)>5), WORKDAY(Mérföldkövek[[#This Row],[Kalkulált kezdés]],1), Mérföldkövek[[#This Row],[Kalkulált kezdés]])) -> 45824 | AD6: =IF(AND(Mérföldkövek[[#This Row],[Volumen]]<>0,Mérföldkövek[[#This Row],[Volumen]]<>"",Mérföldkövek[[#This Row],[Egység idő]]<>0,Mérföldkövek[[#This Row],[Egység idő]]<>""),Mérföldkövek[[#This Row],[Volumen]]*Mérföldkövek[[#This Row],[Egység idő]],0) -> 0.041666667 | AE6: =IF(AND(Mérföldkövek[[#This Row],[Volumen]]<>0,Mérföldkövek[[#This Row],[Volumen]]<>"",Mérföldkövek[[#This Row],[Egység idő]]<>0,Mérföldkövek[[#This Row],[Egység idő]]<>""),Mérföldkövek[[#This Row],[Volumen]]*Mérföldkövek[[#This Row],[Egység idő]]*Mérföldkövek[[#This Row],[Humánerő]],0) -> 0.041666667 | AF6: =IFERROR(Folyamat[[#This Row],[Extra nap]],"") -> 0 | AG6: =ROUNDUP((Mérföldkövek[[#This Row],[Tervezettidő]]*24)/8,0)+Mérföldkövek[[#This Row],[Extra nap]] -> 1 | AH6: =IF(OR(Mérföldkövek[[#This Row],[Kezdés]]<4000,Mérföldkövek[[#This Row],[Napok száma]]=""),0,ROUNDUP((Mérföldkövek[[#This Row],[Napok száma]]-NETWORKDAYS(Mérföldkövek[[#This Row],[Kezdés]],Mérföldkövek[[#This Row],[Kezdés]]+Mérföldkövek[[#This Row],[Napok száma]]-1,0))/2,0)*2) -> 0 | AJ6: {=IF(AND(Mérföldkövek[[#This Row],[Szülő feladat ID]]<>"",Mérföldkövek[[#This Row],[Feladat Függöség Tipusa]]<>""),_xlfn.IFS(Mérföldkövek[[#This Row],[Feladat Függöség Tipusa]]="FF",_xlfn.XLOOKUP(Mérföldkövek[[#This Row],[Szülő feladat ID]],Mérföldkövek[Feladat ID],Mérföldkövek[Befejezés]),Mérföldkövek[[#This Row],[Feladat Függöség Tipusa]]="SF",_xlfn.XLOOKUP(Mérföldkövek[[#This Row],[Szülő feladat ID]],Mérföldkövek[Feladat ID],Mérföldkövek[Kezdés]),TRUE,0),0)} -> 0 | AK6: =IF(OR(Mérföldkövek[[#This Row],[Kezdés]]=0,Mérföldkövek[[#This Row],[Napok száma]]=0),0,Mérföldkövek[[#This Row],[Kezdés]]+Mérföldkövek[[#This Row],[Napok száma]]-1+Mérföldkövek[[#This Row],[Nem munkanap]]) -> 45824 | AL6: {=_xlfn.IFS(Mérföldkövek[[#This Row],[Fixbefejezés]]<>0,Mérföldkövek[[#This Row],[Fixbefejezés]],Mérföldkövek[[#This Row],[Függöbefejezés]]<>0,Mérföldkövek[[#This Row],[Függöbefejezés]],Mérföldkövek[[#This Row],[Kalkulált befejezés]]<>0,Mérföldkövek[[#This Row],[Kalkulált befejezés]],TRUE,0)} -> 45824 | AM6: =IF(OR(WEEKDAY(Mérföldkövek[[#This Row],[Kalkulált befejezés2]],2)>5), WORKDAY(Mérföldkövek[[#This Row],[Kalkulált befejezés2]],1), Mérföldkövek[[#This Row],[Kalkulált befejezés2]]) -> 45824
A7: =IFERROR(Folyamat[[#This Row],[DSMR]],"") -> ProjektSzám | B7: =IFERROR(Folyamat[[#This Row],[Feladat Rövidnév]],"") -> GyI-E.02 | C7: =IFERROR(Mérföldkövek[[#This Row],[Projekt azonosító]] & "-" & Mérföldkövek[[#This Row],[Feladat Rövidnév]],"") -> ProjektSzám-GyI-E.02 | D7: =IFERROR(Folyamat[[#This Row],[Feladat leírás]],"") -> Információk beszerzése | E7: =IFERROR(Folyamat[[#This Row],[Feladat Tipus]],"") -> Folyamat | F7: =IFERROR(Folyamat[[#This Row],[Kockázat]],"") -> Terv szerint | G7: =IFERROR(Folyamat[[#This Row],[Részleg 02]],"") -> Gyártás Iroda | H7: =IFERROR(Folyamat[[#This Row],[Részleg 01]],"") -> Műszaki tervezés | I7: =IFERROR(Folyamat[[#This Row],[Felelős]],"") -> Simon Kázmér | J7: =IFERROR(Folyamat[[#This Row],[Támogató]],"") -> 0 | M7: =IFERROR(Folyamat[[#This Row],[Volumen]],"") -> 1 | N7: =IFERROR(Folyamat[[#This Row],[Egység idő]],"") -> 0.041666667 | O7: =IFERROR(Folyamat[[#This Row],[Humánerő]],"") -> 1 | P7: =IFERROR(IF(Folyamat[[#This Row],[Ősszefoglaló feladat ID]]=0,"",Folyamat[[#This Row],[Ősszefoglaló feladat ID]]),"") -> ProjektSzám-GyI-E.00 | Q7: =IFERROR(IF(Folyamat[[#This Row],[Szülő feladat ID]]=0,"",Folyamat[[#This Row],[Szülő feladat ID]]),"") -> ProjektSzám-GyI-E.01 | R7: =IFERROR(IF(Folyamat[[#This Row],[Feladat Függöség Tipusa]]=0,"",Folyamat[[#This Row],[Feladat Függöség Tipusa]]),"") -> SS | S7: =IFERROR(Folyamat[[#This Row],[Feladat Késleltetés]],"") -> 0 | U7: =IFERROR(Folyamat[[#This Row],[Feladat Elinditása Részleges készültség esetén]],"") -> 1 | V7: =IF(Mérföldkövek[[#This Row],[Szülő feladat ID]]<>"",IF(AND(Mérföldkövek[[#This Row],[Feladat Elinditása Részleges készültség esetén]]<=_xlfn.XLOOKUP(Mérföldkövek[[#This Row],[Szülő feladat ID]],Mérföldkövek[Feladat ID],Mérföldkövek[Készültség]),TODAY()<_xlfn.XLOOKUP(Mérföldkövek[[#This Row],[Szülő feladat ID]],Mérföldkövek[Feladat ID],Mérföldkövek[Befejezés])),TODAY(),0),0) -> 0 | W7: {=IF(AND(Mérföldkövek[[#This Row],[Szülő feladat ID]]<>"",Mérföldkövek[[#This Row],[Feladat Függöség Tipusa]]<>""),_xlfn.IFS(Mérföldkövek[[#This Row],[Feladat Függöség Tipusa]]="FS",_xlfn.XLOOKUP(Mérföldkövek[[#This Row],[Szülő feladat ID]],Mérföldkövek[Feladat ID],Mérföldkövek[Befejezés]+1),Mérföldkövek[[#This Row],[Feladat Függöség Tipusa]]="SS",_xlfn.XLOOKUP(Mérföldkövek[[#This Row],[Szülő feladat ID]],Mérföldkövek[Feladat ID],Mérföldkövek[Kezdés]),TRUE,0),0)} -> 45824 | X7: =Mérföldkövek[[#This Row],[Függökezdés Kalkulált]]+Mérföldkövek[[#This Row],[Feladat Késleltetés]] -> 45824 | Y7: =IF(Mérföldkövek[[#This Row],[Feladat Késleltetés]] = 0,0,IF(Mérföldkövek[[#This Row],[Feladat Késleltetés]]>(NETWORKDAYS(Mérföldkövek[[#This Row],[Függökezdés Kalkulált]],Mérföldkövek[[#This Row],[Függökezdés késleltetett]])-1),Mérföldkövek[[#This Row],[Feladat Késleltetés]]-(NETWORKDAYS(Mérföldkövek[[#This Row],[Függökezdés Kalkulált]],Mérföldkövek[[#This Row],[Függökezdés késleltetett]])-1))) -> 0 | Z7: =IF(OR(WEEKDAY(Mérföldkövek[[#This Row],[Függökezdés Kalkulált]],2)>5), WORKDAY(Mérföldkövek[[#This Row],[Függökezdés Kalkulált]],1), Mérföldkövek[[#This Row],[Függökezdés Kalkulált]]) + Mérföldkövek[[#This Row],[Függökezdés késleltetett plusz]] -> 45824 | AA7: {=_xlfn.IFS(Mérföldkövek[[#This Row],[Fix kexdés]]<>0,Mérföldkövek[[#This Row],[Fix kexdés]],Mérföldkövek[[#This Row],[Részleges Kezdés]]<>0,Mérföldkövek[[#This Row],[Részleges Kezdés]],Mérföldkövek[[#This Row],[Függökezdés]]<>0,Mérföldkövek[[#This Row],[Függökezdés]],TRUE,0)} -> 45824 | AB7: =IF(Mérföldkövek[[#This Row],[Volumen]]<=0,0,IF(OR(WEEKDAY(Mérföldkövek[[#This Row],[Kalkulált kezdés]],2)>5), WORKDAY(Mérföldkövek[[#This Row],[Kalkulált kezdés]],1), Mérföldkövek[[#This Row],[Kalkulált kezdés]])) -> 45824 | AD7: =IF(AND(Mérföldkövek[[#This Row],[Volumen]]<>0,Mérföldkövek[[#This Row],[Volumen]]<>"",Mérföldkövek[[#This Row],[Egység idő]]<>0,Mérföldkövek[[#This Row],[Egység idő]]<>""),Mérföldkövek[[#This Row],[Volumen]]*Mérföldkövek[[#This Row],[Egység idő]],0) -> 0.041666667 | AE7: =IF(AND(Mérföldkövek[[#This Row],[Volumen]]<>0,Mérföldkövek[[#This Row],[Volumen]]<>"",Mérföldkövek[[#This Row],[Egység idő]]<>0,Mérföldkövek[[#This Row],[Egység idő]]<>""),Mérföldkövek[[#This Row],[Volumen]]*Mérföldkövek[[#This Row],[Egység idő]]*Mérföldkövek[[#This Row],[Humánerő]],0) -> 0.041666667 | AF7: =IFERROR(Folyamat[[#This Row],[Extra nap]],"") -> 0 | AG7: =ROUNDUP((Mérföldkövek[[#This Row],[Tervezettidő]]*24)/8,0)+Mérföldkövek[[#This Row],[Extra nap]] -> 1 | AH7: =IF(OR(Mérföldkövek[[#This Row],[Kezdés]]<4000,Mérföldkövek[[#This Row],[Napok száma]]=""),0,ROUNDUP((Mérföldkövek[[#This Row],[Napok száma]]-NETWORKDAYS(Mérföldkövek[[#This Row],[Kezdés]],Mérföldkövek[[#This Row],[Kezdés]]+Mérföldkövek[[#This Row],[Napok száma]]-1,0))/2,0)*2) -> 0 | AJ7: {=IF(AND(Mérföldkövek[[#This Row],[Szülő feladat ID]]<>"",Mérföldkövek[[#This Row],[Feladat Függöség Tipusa]]<>""),_xlfn.IFS(Mérföldkövek[[#This Row],[Feladat Függöség Tipusa]]="FF",_xlfn.XLOOKUP(Mérföldkövek[[#This Row],[Szülő feladat ID]],Mérföldkövek[Feladat ID],Mérföldkövek[Befejezés]),Mérföldkövek[[#This Row],[Feladat Függöség Tipusa]]="SF",_xlfn.XLOOKUP(Mérföldkövek[[#This Row],[Szülő feladat ID]],Mérföldkövek[Feladat ID],Mérföldkövek[Kezdés]),TRUE,0),0)} -> 0 | AK7: =IF(OR(Mérföldkövek[[#This Row],[Kezdés]]=0,Mérföldkövek[[#This Row],[Napok száma]]=0),0,Mérföldkövek[[#This Row],[Kezdés]]+Mérföldkövek[[#This Row],[Napok száma]]-1+Mérföldkövek[[#This Row],[Nem munkanap]]) -> 45824 | AL7: {=_xlfn.IFS(Mérföldkövek[[#This Row],[Fixbefejezés]]<>0,Mérföldkövek[[#This Row],[Fixbefejezés]],Mérföldkövek[[#This Row],[Függöbefejezés]]<>0,Mérföldkövek[[#This Row],[Függöbefejezés]],Mérföldkövek[[#This Row],[Kalkulált befejezés]]<>0,Mérföldkövek[[#This Row],[Kalkulált befejezés]],TRUE,0)} -> 45824 | AM7: =IF(OR(WEEKDAY(Mérföldkövek[[#This Row],[Kalkulált befejezés2]],2)>5), WORKDAY(Mérföldkövek[[#This Row],[Kalkulált befejezés2]],1), Mérföldkövek[[#This Row],[Kalkulált befejezés2]]) -> 45824
